Workbook

Sheet Read Me
C3: SynapticGM Own AI vs Paid APIs — Calculator Read Me
C5: Fresh research project dated 18 August 2026. This workbook is an incremental operating-cash model, not a pricing commitment or revenue forecast.
C6: (£ presentation; editable inputs on Assumptions)
C8: Purpose | D8: Compare the incremental 12-month cash cost of five deployment architectures at 100, 1,000 and 10,000 Free MAU. The central decision is whether a small self-hosted Continuity Warden can earn its own operating complexity before anyone considers a self-hosted narrator.
C10: Scope | D10: Live SynapticGM only. The ledger is truth. The Warden is a narrow classifier, not a custom full narrator. No WOF, no hybrid-climate analysis and no patent analysis are included.
C12: How to use | D12: Change blue cells in Assumptions. Formula cells are black; cross-sheet links are green. Read Cashflow for base-case totals, Sensitivity for cache/retry/art stress, Image Ladder for image route policy, and Sources for dated vendor evidence.
C14: Base workload | D14: 40 turns per Free MAU per month, 5,000 input tokens and 500 output tokens per turn, 30% cache hit, 5% cache-write share when cache is used, 5% API retry rate, and 10× average-to-peak capacity factor.
C16: Cost definition | D16: Includes narrator inference, gate inference, warm GPU capacity, estimated operator hours, evaluation budget, defined API/hosted fallbacks, and baseline art. Excludes revenue, taxes/VAT, payment processing, existing ledger/platform cost, corporate overhead, storage, egress, capital expenditure and any price discount not published.
C18: Interpretation | D18: The self-hosted Warden case deliberately uses a warm $0.27/h 24GB Pod, which makes idle capacity visible. Serverless active-only costs are shown separately but do not receive a free low-latency guarantee. The 7B narrator row is explicitly non-equivalent; the 70B row sizes capacity for a 10× peak and 50 output tok/s/GPU.
C20: Source policy | D20: All price values are public list-price observations from the cited pages, accessed 18 Aug 2026. Some sources are dynamic, model/version-specific or marketplace-based. Recheck before a spend commitment.
C22: Workbook check
C23: Input color audit | D23: Blue = hardcoded/editable input, Black = calculation on same sheet, Green = cross-sheet reference. Every blue hardcode has a source/assumption comment.

Sheet Assumptions
C3: SynapticGM Own AI vs Paid APIs — Assumptions
C5: Editable blue cells drive all calculator outputs; pricing observed 18 Aug 2026.
C6: ($ and £ shown as stated; cost model presents £)
C8: Workload & policy assumptions | F8: Formula check: GBP per USD | G8: =1/D21
C9: MAU low | D9: 100 | F9: Model rule | G9: Do not hard-code cells outside this tab.
C10: MAU mid | D10: 1000 | F10: Exclusion | G10: Revenue, VAT, taxes, existing platform/ledger cost and fixed corporate overhead are excluded as common/non-incremental.
C11: MAU high | D11: 10000
C12: Turns / user / month | D12: 40
C13: Input tokens / turn | D13: 5000
C14: Output tokens / turn | D14: 500
C15: Cache hit rate | D15: 0.3
C16: Cache-write share if caching | D16: 0.05
C17: API retry rate | D17: 0.05
C18: Peak factor vs average | D18: 10
C20: Currency, people and evaluation
C21: USD per GBP | D21: 1.3553
C22: GBP per USD | D22: 0.73784402
C23: Operator £ / hour | D23: 40
C24: Days / month | D24: 30
C25: Hours / month for warm GPU | D25: 730
C26: Weeks / month | D26: 4.3333333
C28: Direct API narrator — Anthropic Sonnet 5 ($ / MTok)
C29: Base input | D29: 2
C30: Cache read | D30: 0.2
C31: 5m cache write | D31: 2.5
C32: Output | D32: 10
C33: OpenRouter planning loading | D33: 0.055
C35: Hosted low-cost gate — Fireworks Nemotron ($ / MTok)
C36: Gate input | D36: 0.05
C37: Gate cached input | D37: 0.01
C38: Gate output | D38: 0.2
C39: Gate input tokens / turn (two passes total) | D39: 2200
C40: Gate output tokens / turn (two passes total) | D40: 80
C41: Hosted-gate narrator retry rate | D41: 0.03
C42: Hosted-gate API fallback rate | D42: 0.01
C44: Self-host hardware and full-narrator capacity
C45: Warden GPU sec / turn (two passes) | D45: 0.6
C46: RunPod warm A5000 24GB $ / GPU-hour | D46: 0.27
C47: RunPod serverless 24GB $ / active GPU-hour | D47: 0.69
C48: Warden hosted-gate fallback rate | D48: 0.01
...

Sheet Cashflow
C3: 12-Month Incremental Cashflow — Own AI vs Paid APIs
C5: Base case: 40 turns/MAU/month; 30% cache hit; 70% art soft-skip; £0.73784/$ planning FX.
C6: (£ per month except where stated; annual column is 12× monthly)
C8: Scenario | D8: MAU | E8: Turns / month | F8: Narrator | G8: Hosted gate | H8: Warm GPU | I8: GPU count | J8: GPU active h | K8: GPU paid h | L8: GPU idle h | M8: Operator | N8: Eval | O8: Failure fallback | P8: Art | Q8: Total / month | R8: Total / 12m | S8: £ / MAU / month
C9: A — OpenRouter-only | D9: =Assumptions!$D$9 | E9: =D9*Assumptions!$D$12 | F9: =E9*(((Assumptions!$D$13/1000000)*(Assumptions!$D$15*Assumptions!$D$30+IF(Assumptions!$D$15>0,Assumptions!$D$16*Assumptions!$D$31,0)+(1-Assumptions!$D$15-IF(Assumptions!$D$15>0,Assumptions!$D$16,0))*Assumptions!$D$29)+(Assumptions!$D$14/1000000)*Assumptions!$D$32)*(1+Assumptions!$D$33))*(1+Assumptions!$D$17)*Assumptions!$D$22 | G9: 0 | H9: 0 | I9: 0 | J9: 0 | K9: 0 | L9: 0 | M9: =1*Assumptions!$D$23 | N9: =25 | O9: 0 | P9: =D9*Assumptions!$D$57*Assumptions!$D$58*Assumptions!$D$26*(1-Assumptions!$D$59)*Assumptions!$D$60*Assumptions!$D$22 | Q9: =SUM(F9:H9,M9:P9) | R9: =Q9*12 | S9: =Q9/D9
C10: A — OpenRouter-only | D10: =Assumptions!$D$10 | E10: =D10*Assumptions!$D$12 | F10: =E10*(((Assumptions!$D$13/1000000)*(Assumptions!$D$15*Assumptions!$D$30+IF(Assumptions!$D$15>0,Assumptions!$D$16*Assumptions!$D$31,0)+(1-Assumptions!$D$15-IF(Assumptions!$D$15>0,Assumptions!$D$16,0))*Assumptions!$D$29)+(Assumptions!$D$14/1000000)*Assumptions!$D$32)*(1+Assumptions!$D$33))*(1+Assumptions!$D$17)*Assumptions!$D$22 | G10: 0 | H10: 0 | I10: 0 | J10: 0 | K10: 0 | L10: 0 | M10: =1*Assumptions!$D$23 | N10: =25 | O10: 0 | P10: =D10*Assumptions!$D$57*Assumptions!$D$58*Assumptions!$D$26*(1-Assumptions!$D$59)*Assumptions!$D$60*Assumptions!$D$22 | Q10: =SUM(F10:H10,M10:P10) | R10: =Q10*12 | S10: =Q10/D10
C11: A — OpenRouter-only | D11: =Assumptions!$D$11 | E11: =D11*Assumptions!$D$12 | F11: =E11*(((Assumptions!$D$13/1000000)*(Assumptions!$D$15*Assumptions!$D$30+IF(Assumptions!$D$15>0,Assumptions!$D$16*Assumptions!$D$31,0)+(1-Assumptions!$D$15-IF(Assumptions!$D$15>0,Assumptions!$D$16,0))*Assumptions!$D$29)+(Assumptions!$D$14/1000000)*Assumptions!$D$32)*(1+Assumptions!$D$33))*(1+Assumptions!$D$17)*Assumptions!$D$22 | G11: 0 | H11: 0 | I11: 0 | J11: 0 | K11: 0 | L11: 0 | M11: =1*Assumptions!$D$23 | N11: =25 | O11: 0 | P11: =D11*Assumptions!$D$57*Assumptions!$D$58*Assumptions!$D$26*(1-Assumptions!$D$59)*Assumptions!$D$60*Assumptions!$D$22 | Q11: =SUM(F11:H11,M11:P11) | R11: =Q11*12 | S11: =Q11/D11
C13: B — Direct APIs + prompt cache | D13: =Assumptions!$D$9 | E13: =D13*Assumptions!$D$12 | F13: =E13*((Assumptions!$D$13/1000000)*(Assumptions!$D$15*Assumptions!$D$30+IF(Assumptions!$D$15>0,Assumptions!$D$16*Assumptions!$D$31,0)+(1-Assumptions!$D$15-IF(Assumptions!$D$15>0,Assumptions!$D$16,0))*Assumptions!$D$29)+(Assumptions!$D$14/1000000)*Assumptions!$D$32)*(1+Assumptions!$D$17)*Assumptions!$D$22 | G13: 0 | H13: 0 | I13: 0 | J13: 0 | K13: 0 | L13: 0 | M13: =2*Assumptions!$D$23 | N13: =40 | O13: 0 | P13: =D13*Assumptions!$D$57*Assumptions!$D$58*Assumptions!$D$26*(1-Assumptions!$D$59)*Assumptions!$D$60*Assumptions!$D$22 | Q13: =SUM(F13:H13,M13:P13) | R13: =Q13*12 | S13: =Q13/D13
C14: B — Direct APIs + prompt cache | D14: =Assumptions!$D$10 | E14: =D14*Assumptions!$D$12 | F14: =E14*((Assumptions!$D$13/1000000)*(Assumptions!$D$15*Assumptions!$D$30+IF(Assumptions!$D$15>0,Assumptions!$D$16*Assumptions!$D$31,0)+(1-Assumptions!$D$15-IF(Assumptions!$D$15>0,Assumptions!$D$16,0))*Assumptions!$D$29)+(Assumptions!$D$14/1000000)*Assumptions!$D$32)*(1+Assumptions!$D$17)*Assumptions!$D$22 | G14: 0 | H14: 0 | I14: 0 | J14: 0 | K14: 0 | L14: 0 | M14: =2*Assumptions!$D$23 | N14: =40 | O14: 0 | P14: =D14*Assumptions!$D$57*Assumptions!$D$58*Assumptions!$D$26*(1-Assumptions!$D$59)*Assumptions!$D$60*Assumptions!$D$22 | Q14: =SUM(F14:H14,M14:P14) | R14: =Q14*12 | S14: =Q14/D14
C15: B — Direct APIs + prompt cache | D15: =Assumptions!$D$11 | E15: =D15*Assumptions!$D$12 | F15: =E15*((Assumptions!$D$13/1000000)*(Assumptions!$D$15*Assumptions!$D$30+IF(Assumptions!$D$15>0,Assumptions!$D$16*Assumptions!$D$31,0)+(1-Assumptions!$D$15-IF(Assumptions!$D$15>0,Assumptions!$D$16,0))*Assumptions!$D$29)+(Assumptions!$D$14/1000000)*Assumptions!$D$32)*(1+Assumptions!$D$17)*Assumptions!$D$22 | G15: 0 | H15: 0 | I15: 0 | J15: 0 | K15: 0 | L15: 0 | M15: =2*Assumptions!$D$23 | N15: =40 | O15: 0 | P15: =D15*Assumptions!$D$57*Assumptions!$D$58*Assumptions!$D$26*(1-Assumptions!$D$59)*Assumptions!$D$60*Assumptions!$D$22 | Q15: =SUM(F15:H15,M15:P15) | R15: =Q15*12 | S15: =Q15/D15
C17: C — Hosted low-cost gates + mid narrator | D17: =Assumptions!$D$9 | E17: =D17*Assumptions!$D$12 | F17: =E17*((Assumptions!$D$13/1000000)*(Assumptions!$D$15*Assumptions!$D$30+IF(Assumptions!$D$15>0,Assumptions!$D$16*Assumptions!$D$31,0)+(1-Assumptions!$D$15-IF(Assumptions!$D$15>0,Assumptions!$D$16,0))*Assumptions!$D$29)+(Assumptions!$D$14/1000000)*Assumptions!$D$32)*(1+Assumptions!$D$41)*Assumptions!$D$22 | G17: =E17*((Assumptions!$D$39/1000000)*(Assumptions!$D$15*Assumptions!$D$37+(1-Assumptions!$D$15)*Assumptions!$D$36)+(Assumptions!$D$40/1000000)*Assumptions!$D$38)*Assumptions!$D$22 | H17: 0 | I17: 0 | J17: 0 | K17: 0 | L17: 0 | M17: =3*Assumptions!$D$23 | N17: =60 | O17: =E17*Assumptions!$D$42*((Assumptions!$D$13/1000000)*(Assumptions!$D$15*Assumptions!$D$30+IF(Assumptions!$D$15>0,Assumptions!$D$16*Assumptions!$D$31,0)+(1-Assumptions!$D$15-IF(Assumptions!$D$15>0,Assumptions!$D$16,0))*Assumptions!$D$29)+(Assumptions!$D$14/1000000)*Assumptions!$D$32)*Assumptions!$D$22 | P17: =D17*Assumptions!$D$57*Assumptions!$D$58*Assumptions!$D$26*(1-Assumptions!$D$59)*Assumptions!$D$60*Assumptions!$D$22 | Q17: =SUM(F17:H17,M17:P17) | R17: =Q17*12 | S17: =Q17/D17
C18: C — Hosted low-cost gates + mid narrator | D18: =Assumptions!$D$10 | E18: =D18*Assumptions!$D$12 | F18: =E18*((Assumptions!$D$13/1000000)*(Assumptions!$D$15*Assumptions!$D$30+IF(Assumptions!$D$15>0,Assumptions!$D$16*Assumptions!$D$31,0)+(1-Assumptions!$D$15-IF(Assumptions!$D$15>0,Assumptions!$D$16,0))*Assumptions!$D$29)+(Assumptions!$D$14/1000000)*Assumptions!$D$32)*(1+Assumptions!$D$41)*Assumptions!$D$22 | G18: =E18*((Assumptions!$D$39/1000000)*(Assumptions!$D$15*Assumptions!$D$37+(1-Assumptions!$D$15)*Assumptions!$D$36)+(Assumptions!$D$40/1000000)*Assumptions!$D$38)*Assumptions!$D$22 | H18: 0 | I18: 0 | J18: 0 | K18: 0 | L18: 0 | M18: =3*Assumptions!$D$23 | N18: =60 | O18: =E18*Assumptions!$D$42*((Assumptions!$D$13/1000000)*(Assumptions!$D$15*Assumptions!$D$30+IF(Assumptions!$D$15>0,Assumptions!$D$16*Assumptions!$D$31,0)+(1-Assumptions!$D$15-IF(Assumptions!$D$15>0,Assumptions!$D$16,0))*Assumptions!$D$29)+(Assumptions!$D$14/1000000)*Assumptions!$D$32)*Assumptions!$D$22 | P18: =D18*Assumptions!$D$57*Assumptions!$D$58*Assumptions!$D$26*(1-Assumptions!$D$59)*Assumptions!$D$60*Assumptions!$D$22 | Q18: =SUM(F18:H18,M18:P18) | R18: =Q18*12 | S18: =Q18/D18
C19: C — Hosted low-cost gates + mid narrator | D19: =Assumptions!$D$11 | E19: =D19*Assumptions!$D$12 | F19: =E19*((Assumptions!$D$13/1000000)*(Assumptions!$D$15*Assumptions!$D$30+IF(Assumptions!$D$15>0,Assumptions!$D$16*Assumptions!$D$31,0)+(1-Assumptions!$D$15-IF(Assumptions!$D$15>0,Assumptions!$D$16,0))*Assumptions!$D$29)+(Assumptions!$D$14/1000000)*Assumptions!$D$32)*(1+Assumptions!$D$41)*Assumptions!$D$22 | G19: =E19*((Assumptions!$D$39/1000000)*(Assumptions!$D$15*Assumptions!$D$37+(1-Assumptions!$D$15)*Assumptions!$D$36)+(Assumptions!$D$40/1000000)*Assumptions!$D$38)*Assumptions!$D$22 | H19: 0 | I19: 0 | J19: 0 | K19: 0 | L19: 0 | M19: =3*Assumptions!$D$23 | N19: =60 | O19: =E19*Assumptions!$D$42*((Assumptions!$D$13/1000000)*(Assumptions!$D$15*Assumptions!$D$30+IF(Assumptions!$D$15>0,Assumptions!$D$16*Assumptions!$D$31,0)+(1-Assumptions!$D$15-IF(Assumptions!$D$15>0,Assumptions!$D$16,0))*Assumptions!$D$29)+(Assumptions!$D$14/1000000)*Assumptions!$D$32)*Assumptions!$D$22 | P19: =D19*Assumptions!$D$57*Assumptions!$D$58*Assumptions!$D$26*(1-Assumptions!$D$59)*Assumptions!$D$60*Assumptions!$D$22 | Q19: =SUM(F19:H19,M19:P19) | R19: =Q19*12 | S19: =Q19/D19
C21: D — Self-host Continuity Warden only | D21: =Assumptions!$D$9 | E21: =D21*Assumptions!$D$12 | F21: =E21*((Assumptions!$D$13/1000000)*(Assumptions!$D$15*Assumptions!$D$30+IF(Assumptions!$D$15>0,Assumptions!$D$16*Assumptions!$D$31,0)+(1-Assumptions!$D$15-IF(Assumptions!$D$15>0,Assumptions!$D$16,0))*Assumptions!$D$29)+(Assumptions!$D$14/1000000)*Assumptions!$D$32)*(1+Assumptions!$D$17)*Assumptions!$D$22 | G21: 0 | H21: =K21*Assumptions!$D$46*Assumptions!$D$22 | I21: =MAX(1,ROUNDUP((E21/(Assumptions!$D$24*24*3600))*Assumptions!$D$18*Assumptions!$D$45,0)) | J21: =E21*Assumptions!$D$45/3600 | K21: =I21*Assumptions!$D$25 | L21: =MAX(0,K21-J21) | M21: =6*Assumptions!$D$23 | N21: =100 | O21: =E21*Assumptions!$D$48*((Assumptions!$D$39/1000000)*(Assumptions!$D$15*Assumptions!$D$37+(1-Assumptions!$D$15)*Assumptions!$D$36)+(Assumptions!$D$40/1000000)*Assumptions!$D$38)*Assumptions!$D$22 | P21: =D21*Assumptions!$D$57*Assumptions!$D$58*Assumptions!$D$26*(1-Assumptions!$D$59)*Assumptions!$D$60*Assumptions!$D$22 | Q21: =SUM(F21:H21,M21:P21) | R21: =Q21*12 | S21: =Q21/D21
C22: D — Self-host Continuity Warden only | D22: =Assumptions!$D$10 | E22: =D22*Assumptions!$D$12 | F22: =E22*((Assumptions!$D$13/1000000)*(Assumptions!$D$15*Assumptions!$D$30+IF(Assumptions!$D$15>0,Assumptions!$D$16*Assumptions!$D$31,0)+(1-Assumptions!$D$15-IF(Assumptions!$D$15>0,Assumptions!$D$16,0))*Assumptions!$D$29)+(Assumptions!$D$14/1000000)*Assumptions!$D$32)*(1+Assumptions!$D$17)*Assumptions!$D$22 | G22: 0 | H22: =K22*Assumptions!$D$46*Assumptions!$D$22 | I22: =MAX(1,ROUNDUP((E22/(Assumptions!$D$24*24*3600))*Assumptions!$D$18*Assumptions!$D$45,0)) | J22: =E22*Assumptions!$D$45/3600 | K22: =I22*Assumptions!$D$25 | L22: =MAX(0,K22-J22) | M22: =6*Assumptions!$D$23 | N22: =100 | O22: =E22*Assumptions!$D$48*((Assumptions!$D$39/1000000)*(Assumptions!$D$15*Assumptions!$D$37+(1-Assumptions!$D$15)*Assumptions!$D$36)+(Assumptions!$D$40/1000000)*Assumptions!$D$38)*Assumptions!$D$22 | P22: =D22*Assumptions!$D$57*Assumptions!$D$58*Assumptions!$D$26*(1-Assumptions!$D$59)*Assumptions!$D$60*Assumptions!$D$22 | Q22: =SUM(F22:H22,M22:P22) | R22: =Q22*12 | S22: =Q22/D22
C23: D — Self-host Continuity Warden only | D23: =Assumptions!$D$11 | E23: =D23*Assumptions!$D$12 | F23: =E23*((Assumptions!$D$13/1000000)*(Assumptions!$D$15*Assumptions!$D$30+IF(Assumptions!$D$15>0,Assumptions!$D$16*Assumptions!$D$31,0)+(1-Assumptions!$D$15-IF(Assumptions!$D$15>0,Assumptions!$D$16,0))*Assumptions!$D$29)+(Assumptions!$D$14/1000000)*Assumptions!$D$32)*(1+Assumptions!$D$17)*Assumptions!$D$22 | G23: 0 | H23: =K23*Assumptions!$D$46*Assumptions!$D$22 | I23: =MAX(1,ROUNDUP((E23/(Assumptions!$D$24*24*3600))*Assumptions!$D$18*Assumptions!$D$45,0)) | J23: =E23*Assumptions!$D$45/3600 | K23: =I23*Assumptions!$D$25 | L23: =MAX(0,K23-J23) | M23: =6*Assumptions!$D$23 | N23: =100 | O23: =E23*Assumptions!$D$48*((Assumptions!$D$39/1000000)*(Assumptions!$D$15*Assumptions!$D$37+(1-Assumptions!$D$15)*Assumptions!$D$36)+(Assumptions!$D$40/1000000)*Assumptions!$D$38)*Assumptions!$D$22 | P23: =D23*Assumptions!$D$57*Assumptions!$D$58*Assumptions!$D$26*(1-Assumptions!$D$59)*Assumptions!$D$60*Assumptions!$D$22 | Q23: =SUM(F23:H23,M23:P23) | R23: =Q23*12 | S23: =Q23/D23
C25: E1 — Self-host full 7B narrator (production fallback) | D25: =Assumptions!$D$9 | E25: =D25*Assumptions!$D$12 | F25: 0 | G25: 0 | H25: =K25*Assumptions!$D$50*Assumptions!$D$22 | I25: =MAX(1,ROUNDUP(((E25/(Assumptions!$D$24*24*3600))*Assumptions!$D$18*Assumptions!$D$14)/Assumptions!$D$49,0)) | J25: =E25*Assumptions!$D$14/Assumptions!$D$49/3600 | K25: =I25*Assumptions!$D$25 | L25: =MAX(0,K25-J25) | M25: =8*Assumptions!$D$23 | N25: =150 | O25: =E25*Assumptions!$D$51*((Assumptions!$D$13/1000000)*(Assumptions!$D$15*Assumptions!$D$30+IF(Assumptions!$D$15>0,Assumptions!$D$16*Assumptions!$D$31,0)+(1-Assumptions!$D$15-IF(Assumptions!$D$15>0,Assumptions!$D$16,0))*Assumptions!$D$29)+(Assumptions!$D$14/1000000)*Assumptions!$D$32)*Assumptions!$D$22 | P25: =D25*Assumptions!$D$57*Assumptions!$D$58*Assumptions!$D$26*(1-Assumptions!$D$59)*Assumptions!$D$60*Assumptions!$D$22 | Q25: =SUM(F25:H25,M25:P25) | R25: =Q25*12 | S25: =Q25/D25
C26: E1 — Self-host full 7B narrator (production fallback) | D26: =Assumptions!$D$10 | E26: =D26*Assumptions!$D$12 | F26: 0 | G26: 0 | H26: =K26*Assumptions!$D$50*Assumptions!$D$22 | I26: =MAX(1,ROUNDUP(((E26/(Assumptions!$D$24*24*3600))*Assumptions!$D$18*Assumptions!$D$14)/Assumptions!$D$49,0)) | J26: =E26*Assumptions!$D$14/Assumptions!$D$49/3600 | K26: =I26*Assumptions!$D$25 | L26: =MAX(0,K26-J26) | M26: =8*Assumptions!$D$23 | N26: =150 | O26: =E26*Assumptions!$D$51*((Assumptions!$D$13/1000000)*(Assumptions!$D$15*Assumptions!$D$30+IF(Assumptions!$D$15>0,Assumptions!$D$16*Assumptions!$D$31,0)+(1-Assumptions!$D$15-IF(Assumptions!$D$15>0,Assumptions!$D$16,0))*Assumptions!$D$29)+(Assumptions!$D$14/1000000)*Assumptions!$D$32)*Assumptions!$D$22 | P26: =D26*Assumptions!$D$57*Assumptions!$D$58*Assumptions!$D$26*(1-Assumptions!$D$59)*Assumptions!$D$60*Assumptions!$D$22 | Q26: =SUM(F26:H26,M26:P26) | R26: =Q26*12 | S26: =Q26/D26
C27: E1 — Self-host full 7B narrator (production fallback) | D27: =Assumptions!$D$11 | E27: =D27*Assumptions!$D$12 | F27: 0 | G27: 0 | H27: =K27*Assumptions!$D$50*Assumptions!$D$22 | I27: =MAX(1,ROUNDUP(((E27/(Assumptions!$D$24*24*3600))*Assumptions!$D$18*Assumptions!$D$14)/Assumptions!$D$49,0)) | J27: =E27*Assumptions!$D$14/Assumptions!$D$49/3600 | K27: =I27*Assumptions!$D$25 | L27: =MAX(0,K27-J27) | M27: =8*Assumptions!$D$23 | N27: =150 | O27: =E27*Assumptions!$D$51*((Assumptions!$D$13/1000000)*(Assumptions!$D$15*Assumptions!$D$30+IF(Assumptions!$D$15>0,Assumptions!$D$16*Assumptions!$D$31,0)+(1-Assumptions!$D$15-IF(Assumptions!$D$15>0,Assumptions!$D$16,0))*Assumptions!$D$29)+(Assumptions!$D$14/1000000)*Assumptions!$D$32)*Assumptions!$D$22 | P27: =D27*Assumptions!$D$57*Assumptions!$D$58*Assumptions!$D$26*(1-Assumptions!$D$59)*Assumptions!$D$60*Assumptions!$D$22 | Q27: =SUM(F27:H27,M27:P27) | R27: =Q27*12 | S27: =Q27/D27
C29: E2 — Self-host full 70B narrator | D29: =Assumptions!$D$9 | E29: =D29*Assumptions!$D$12 | F29: 0 | G29: 0 | H29: =K29*Assumptions!$D$53*Assumptions!$D$22 | I29: =MAX(1,ROUNDUP(((E29/(Assumptions!$D$24*24*3600))*Assumptions!$D$18*Assumptions!$D$14)/Assumptions!$D$52,0)) | J29: =E29*Assumptions!$D$14/Assumptions!$D$52/3600 | K29: =I29*Assumptions!$D$25 | L29: =MAX(0,K29-J29) | M29: =14*Assumptions!$D$23 | N29: =300 | O29: =E29*Assumptions!$D$54*((Assumptions!$D$13/1000000)*(Assumptions!$D$15*Assumptions!$D$30+IF(Assumptions!$D$15>0,Assumptions!$D$16*Assumptions!$D$31,0)+(1-Assumptions!$D$15-IF(Assumptions!$D$15>0,Assumptions!$D$16,0))*Assumptions!$D$29)+(Assumptions!$D$14/1000000)*Assumptions!$D$32)*Assumptions!$D$22 | P29: =D29*Assumptions!$D$57*Assumptions!$D$58*Assumptions!$D$26*(1-Assumptions!$D$59)*Assumptions!$D$60*Assumptions!$D$22 | Q29: =SUM(F29:H29,M29:P29) | R29: =Q29*12 | S29: =Q29/D29
C30: E2 — Self-host full 70B narrator | D30: =Assumptions!$D$10 | E30: =D30*Assumptions!$D$12 | F30: 0 | G30: 0 | H30: =K30*Assumptions!$D$53*Assumptions!$D$22 | I30: =MAX(1,ROUNDUP(((E30/(Assumptions!$D$24*24*3600))*Assumptions!$D$18*Assumptions!$D$14)/Assumptions!$D$52,0)) | J30: =E30*Assumptions!$D$14/Assumptions!$D$52/3600 | K30: =I30*Assumptions!$D$25 | L30: =MAX(0,K30-J30) | M30: =14*Assumptions!$D$23 | N30: =300 | O30: =E30*Assumptions!$D$54*((Assumptions!$D$13/1000000)*(Assumptions!$D$15*Assumptions!$D$30+IF(Assumptions!$D$15>0,Assumptions!$D$16*Assumptions!$D$31,0)+(1-Assumptions!$D$15-IF(Assumptions!$D$15>0,Assumptions!$D$16,0))*Assumptions!$D$29)+(Assumptions!$D$14/1000000)*Assumptions!$D$32)*Assumptions!$D$22 | P30: =D30*Assumptions!$D$57*Assumptions!$D$58*Assumptions!$D$26*(1-Assumptions!$D$59)*Assumptions!$D$60*Assumptions!$D$22 | Q30: =SUM(F30:H30,M30:P30) | R30: =Q30*12 | S30: =Q30/D30
C31: E2 — Self-host full 70B narrator | D31: =Assumptions!$D$11 | E31: =D31*Assumptions!$D$12 | F31: 0 | G31: 0 | H31: =K31*Assumptions!$D$53*Assumptions!$D$22 | I31: =MAX(1,ROUNDUP(((E31/(Assumptions!$D$24*24*3600))*Assumptions!$D$18*Assumptions!$D$14)/Assumptions!$D$52,0)) | J31: =E31*Assumptions!$D$14/Assumptions!$D$52/3600 | K31: =I31*Assumptions!$D$25 | L31: =MAX(0,K31-J31) | M31: =14*Assumptions!$D$23 | N31: =300 | O31: =E31*Assumptions!$D$54*((Assumptions!$D$13/1000000)*(Assumptions!$D$15*Assumptions!$D$30+IF(Assumptions!$D$15>0,Assumptions!$D$16*Assumptions!$D$31,0)+(1-Assumptions!$D$15-IF(Assumptions!$D$15>0,Assumptions!$D$16,0))*Assumptions!$D$29)+(Assumptions!$D$14/1000000)*Assumptions!$D$32)*Assumptions!$D$22 | P31: =D31*Assumptions!$D$57*Assumptions!$D$58*Assumptions!$D$26*(1-Assumptions!$D$59)*Assumptions!$D$60*Assumptions!$D$22 | Q31: =SUM(F31:H31,M31:P31) | R31: =Q31*12 | S31: =Q31/D31
C34: Interpretation controls
C35: • A is a planning OpenRouter gross-up, not a claim of universal transaction fees. Model-route prices vary by provider.
C36: • B–D use the same direct Sonnet 5 mid-narrator workload to isolate routing/gate/warden economics.
C37: • D models a warm production pod to expose idle cost. A scale-to-zero serverless Warden is reported separately in Sensitivity.
C38: • E1 assumes 85% paid-API fallback because a 7B narrator is not granted quality parity without evaluation proof; E2 is a quality-aspirational 70B capacity case. Neither is asserted to match paid narrator quality without benchmark proof.
C39: • GPU idle hours are paid warm hours minus estimated active compute hours. Active hours do not include cold starts, storage, egress or monitoring overhead.
C40: • Art is a common direct BFL baseline at a planning cap of one attempt per weekly-active user per week, 60% WAU/MAU, with a 70% soft skip rate.
C43: Chart helper: monthly £ by scenario at 1,000 MAU
C44: Scenario | D44: Monthly £
C45: A — OpenRouter-only | D45: =Q10
C46: B — Direct APIs + prompt cache | D46: =Q14
C47: C — Hosted low-cost gates + mid narrator | D47: =Q18
C48: D — Self-host Continuity Warden only | D48: =Q22
C49: E1 — Self-host full 7B narrator (production fallback) | D49: =Q26
C50: E2 — Self-host full 70B narrator | D50: =Q30

Sheet Sensitivity
C3: Break-Even Calculator and Sensitivities
C5: Every denominator and workload variable is editable on Assumptions. Use this tab to stress cache, retry, art skip, and Warden deployment mode.
C6: (£ unless stated)
C8: Core spreadsheet-friendly formulas
C9: Monthly turns | D9: MAU × turns/user/month
C10: Narrator $/turn | D10: (Input tokens ÷ 1,000,000 × [H×cache-read + W×cache-write + (1−H−W)×base-input]) + (Output tokens ÷ 1,000,000 × output rate)
C11: Narrator £/month | D11: Monthly turns × narrator $/turn × (1 + retry rate) × GBP/USD
C12: Art £/month | D12: MAU × WAU share × weekly cap × weeks/month × (1−art skip) × $/image × GBP/USD
C13: Warm GPU £/month | D13: GPU count × warm hours/month × $/GPU-hour × GBP/USD
C14: Warden GPU count | D14: MAX(1, CEILING(avg turns/sec × peak factor × GPU seconds/turn, 1))
C15: Full narrator GPU count | D15: MAX(1, CEILING(peak turns/sec × output tokens/turn ÷ output tokens/sec/GPU, 1))
C16: Break-even MAU vs paid API | D16: (self-host fixed £/month − paid fixed £/month) ÷ (paid variable £/MAU/month − self-host variable £/MAU/month)
C18: Cache-hit sensitivity — Direct APIs + prompt cache
C19: Cache hit | D19: 100 MAU monthly £ | E19: 1,000 MAU monthly £ | F19: 10,000 MAU monthly £ | G19: Narrator $/turn
C20: 0 | D20: =Assumptions!$D$9*Assumptions!$D$12*((Assumptions!$D$13/1000000)*($C20*Assumptions!$D$30+IF($C20>0,Assumptions!$D$16*Assumptions!$D$31,0)+(1-$C20-IF($C20>0,Assumptions!$D$16,0))*Assumptions!$D$29)+(Assumptions!$D$14/1000000)*Assumptions!$D$32)*(1+Assumptions!$D$17)*Assumptions!$D$22+(Assumptions!$D$9*Assumptions!$D$57*Assumptions!$D$58*Assumptions!$D$26*(1-Assumptions!$D$59)*Assumptions!$D$60*Assumptions!$D$22)+2*Assumptions!$D$23+40 | E20: =Assumptions!$D$10*Assumptions!$D$12*((Assumptions!$D$13/1000000)*($C20*Assumptions!$D$30+IF($C20>0,Assumptions!$D$16*Assumptions!$D$31,0)+(1-$C20-IF($C20>0,Assumptions!$D$16,0))*Assumptions!$D$29)+(Assumptions!$D$14/1000000)*Assumptions!$D$32)*(1+Assumptions!$D$17)*Assumptions!$D$22+(Assumptions!$D$10*Assumptions!$D$57*Assumptions!$D$58*Assumptions!$D$26*(1-Assumptions!$D$59)*Assumptions!$D$60*Assumptions!$D$22)+2*Assumptions!$D$23+40 | F20: =Assumptions!$D$11*Assumptions!$D$12*((Assumptions!$D$13/1000000)*($C20*Assumptions!$D$30+IF($C20>0,Assumptions!$D$16*Assumptions!$D$31,0)+(1-$C20-IF($C20>0,Assumptions!$D$16,0))*Assumptions!$D$29)+(Assumptions!$D$14/1000000)*Assumptions!$D$32)*(1+Assumptions!$D$17)*Assumptions!$D$22+(Assumptions!$D$11*Assumptions!$D$57*Assumptions!$D$58*Assumptions!$D$26*(1-Assumptions!$D$59)*Assumptions!$D$60*Assumptions!$D$22)+2*Assumptions!$D$23+40 | H20: =((Assumptions!$D$13/1000000)*($C20*Assumptions!$D$30+IF($C20>0,Assumptions!$D$16*Assumptions!$D$31,0)+(1-$C20-IF($C20>0,Assumptions!$D$16,0))*Assumptions!$D$29)+(Assumptions!$D$14/1000000)*Assumptions!$D$32)
C21: 0.3 | D21: =Assumptions!$D$9*Assumptions!$D$12*((Assumptions!$D$13/1000000)*($C21*Assumptions!$D$30+IF($C21>0,Assumptions!$D$16*Assumptions!$D$31,0)+(1-$C21-IF($C21>0,Assumptions!$D$16,0))*Assumptions!$D$29)+(Assumptions!$D$14/1000000)*Assumptions!$D$32)*(1+Assumptions!$D$17)*Assumptions!$D$22+(Assumptions!$D$9*Assumptions!$D$57*Assumptions!$D$58*Assumptions!$D$26*(1-Assumptions!$D$59)*Assumptions!$D$60*Assumptions!$D$22)+2*Assumptions!$D$23+40 | E21: =Assumptions!$D$10*Assumptions!$D$12*((Assumptions!$D$13/1000000)*($C21*Assumptions!$D$30+IF($C21>0,Assumptions!$D$16*Assumptions!$D$31,0)+(1-$C21-IF($C21>0,Assumptions!$D$16,0))*Assumptions!$D$29)+(Assumptions!$D$14/1000000)*Assumptions!$D$32)*(1+Assumptions!$D$17)*Assumptions!$D$22+(Assumptions!$D$10*Assumptions!$D$57*Assumptions!$D$58*Assumptions!$D$26*(1-Assumptions!$D$59)*Assumptions!$D$60*Assumptions!$D$22)+2*Assumptions!$D$23+40 | F21: =Assumptions!$D$11*Assumptions!$D$12*((Assumptions!$D$13/1000000)*($C21*Assumptions!$D$30+IF($C21>0,Assumptions!$D$16*Assumptions!$D$31,0)+(1-$C21-IF($C21>0,Assumptions!$D$16,0))*Assumptions!$D$29)+(Assumptions!$D$14/1000000)*Assumptions!$D$32)*(1+Assumptions!$D$17)*Assumptions!$D$22+(Assumptions!$D$11*Assumptions!$D$57*Assumptions!$D$58*Assumptions!$D$26*(1-Assumptions!$D$59)*Assumptions!$D$60*Assumptions!$D$22)+2*Assumptions!$D$23+40 | H21: =((Assumptions!$D$13/1000000)*($C21*Assumptions!$D$30+IF($C21>0,Assumptions!$D$16*Assumptions!$D$31,0)+(1-$C21-IF($C21>0,Assumptions!$D$16,0))*Assumptions!$D$29)+(Assumptions!$D$14/1000000)*Assumptions!$D$32)
C22: 0.7 | D22: =Assumptions!$D$9*Assumptions!$D$12*((Assumptions!$D$13/1000000)*($C22*Assumptions!$D$30+IF($C22>0,Assumptions!$D$16*Assumptions!$D$31,0)+(1-$C22-IF($C22>0,Assumptions!$D$16,0))*Assumptions!$D$29)+(Assumptions!$D$14/1000000)*Assumptions!$D$32)*(1+Assumptions!$D$17)*Assumptions!$D$22+(Assumptions!$D$9*Assumptions!$D$57*Assumptions!$D$58*Assumptions!$D$26*(1-Assumptions!$D$59)*Assumptions!$D$60*Assumptions!$D$22)+2*Assumptions!$D$23+40 | E22: =Assumptions!$D$10*Assumptions!$D$12*((Assumptions!$D$13/1000000)*($C22*Assumptions!$D$30+IF($C22>0,Assumptions!$D$16*Assumptions!$D$31,0)+(1-$C22-IF($C22>0,Assumptions!$D$16,0))*Assumptions!$D$29)+(Assumptions!$D$14/1000000)*Assumptions!$D$32)*(1+Assumptions!$D$17)*Assumptions!$D$22+(Assumptions!$D$10*Assumptions!$D$57*Assumptions!$D$58*Assumptions!$D$26*(1-Assumptions!$D$59)*Assumptions!$D$60*Assumptions!$D$22)+2*Assumptions!$D$23+40 | F22: =Assumptions!$D$11*Assumptions!$D$12*((Assumptions!$D$13/1000000)*($C22*Assumptions!$D$30+IF($C22>0,Assumptions!$D$16*Assumptions!$D$31,0)+(1-$C22-IF($C22>0,Assumptions!$D$16,0))*Assumptions!$D$29)+(Assumptions!$D$14/1000000)*Assumptions!$D$32)*(1+Assumptions!$D$17)*Assumptions!$D$22+(Assumptions!$D$11*Assumptions!$D$57*Assumptions!$D$58*Assumptions!$D$26*(1-Assumptions!$D$59)*Assumptions!$D$60*Assumptions!$D$22)+2*Assumptions!$D$23+40 | H22: =((Assumptions!$D$13/1000000)*($C22*Assumptions!$D$30+IF($C22>0,Assumptions!$D$16*Assumptions!$D$31,0)+(1-$C22-IF($C22>0,Assumptions!$D$16,0))*Assumptions!$D$29)+(Assumptions!$D$14/1000000)*Assumptions!$D$32)
C24: Retry-rate sensitivity — Direct APIs + prompt cache at 1,000 MAU
C25: Retry rate | D25: Narrator £/month | E25: Total £/month | F25: Incremental vs 0%
C26: 0 | D26: =Assumptions!$D$10*Assumptions!$D$12*((Assumptions!$D$13/1000000)*(Assumptions!$D$15*Assumptions!$D$30+IF(Assumptions!$D$15>0,Assumptions!$D$16*Assumptions!$D$31,0)+(1-Assumptions!$D$15-IF(Assumptions!$D$15>0,Assumptions!$D$16,0))*Assumptions!$D$29)+(Assumptions!$D$14/1000000)*Assumptions!$D$32)*(1+$C26)*Assumptions!$D$22 | E26: =D26+(Assumptions!$D$10*Assumptions!$D$57*Assumptions!$D$58*Assumptions!$D$26*(1-Assumptions!$D$59)*Assumptions!$D$60*Assumptions!$D$22)+2*Assumptions!$D$23+40 | F26: =E26-$E$26
C27: 0.05 | D27: =Assumptions!$D$10*Assumptions!$D$12*((Assumptions!$D$13/1000000)*(Assumptions!$D$15*Assumptions!$D$30+IF(Assumptions!$D$15>0,Assumptions!$D$16*Assumptions!$D$31,0)+(1-Assumptions!$D$15-IF(Assumptions!$D$15>0,Assumptions!$D$16,0))*Assumptions!$D$29)+(Assumptions!$D$14/1000000)*Assumptions!$D$32)*(1+$C27)*Assumptions!$D$22 | E27: =D27+(Assumptions!$D$10*Assumptions!$D$57*Assumptions!$D$58*Assumptions!$D$26*(1-Assumptions!$D$59)*Assumptions!$D$60*Assumptions!$D$22)+2*Assumptions!$D$23+40 | F27: =E27-$E$26
C28: 0.15 | D28: =Assumptions!$D$10*Assumptions!$D$12*((Assumptions!$D$13/1000000)*(Assumptions!$D$15*Assumptions!$D$30+IF(Assumptions!$D$15>0,Assumptions!$D$16*Assumptions!$D$31,0)+(1-Assumptions!$D$15-IF(Assumptions!$D$15>0,Assumptions!$D$16,0))*Assumptions!$D$29)+(Assumptions!$D$14/1000000)*Assumptions!$D$32)*(1+$C28)*Assumptions!$D$22 | E28: =D28+(Assumptions!$D$10*Assumptions!$D$57*Assumptions!$D$58*Assumptions!$D$26*(1-Assumptions!$D$59)*Assumptions!$D$60*Assumptions!$D$22)+2*Assumptions!$D$23+40 | F28: =E28-$E$26
C30: Art soft-skip sensitivity — 1 MP BFL/FLUX.2 Pro cash spend
C31: Art skip rate | D31: 100 MAU £/month | E31: 1,000 MAU £/month | F31: 10,000 MAU £/month | G31: Image attempts / 10k MAU / month
C32: 0 | D32: =Assumptions!$D$9*Assumptions!$D$57*Assumptions!$D$58*Assumptions!$D$26*(1-$C32)*Assumptions!$D$60*Assumptions!$D$22 | E32: =Assumptions!$D$10*Assumptions!$D$57*Assumptions!$D$58*Assumptions!$D$26*(1-$C32)*Assumptions!$D$60*Assumptions!$D$22 | F32: =Assumptions!$D$11*Assumptions!$D$57*Assumptions!$D$58*Assumptions!$D$26*(1-$C32)*Assumptions!$D$60*Assumptions!$D$22 | H32: =Assumptions!$D$11*Assumptions!$D$57*Assumptions!$D$58*Assumptions!$D$26*(1-$C32)
C33: 0.3 | D33: =Assumptions!$D$9*Assumptions!$D$57*Assumptions!$D$58*Assumptions!$D$26*(1-$C33)*Assumptions!$D$60*Assumptions!$D$22 | E33: =Assumptions!$D$10*Assumptions!$D$57*Assumptions!$D$58*Assumptions!$D$26*(1-$C33)*Assumptions!$D$60*Assumptions!$D$22 | F33: =Assumptions!$D$11*Assumptions!$D$57*Assumptions!$D$58*Assumptions!$D$26*(1-$C33)*Assumptions!$D$60*Assumptions!$D$22 | H33: =Assumptions!$D$11*Assumptions!$D$57*Assumptions!$D$58*Assumptions!$D$26*(1-$C33)
C34: 0.7 | D34: =Assumptions!$D$9*Assumptions!$D$57*Assumptions!$D$58*Assumptions!$D$26*(1-$C34)*Assumptions!$D$60*Assumptions!$D$22 | E34: =Assumptions!$D$10*Assumptions!$D$57*Assumptions!$D$58*Assumptions!$D$26*(1-$C34)*Assumptions!$D$60*Assumptions!$D$22 | F34: =Assumptions!$D$11*Assumptions!$D$57*Assumptions!$D$58*Assumptions!$D$26*(1-$C34)*Assumptions!$D$60*Assumptions!$D$22 | H34: =Assumptions!$D$11*Assumptions!$D$57*Assumptions!$D$58*Assumptions!$D$26*(1-$C34)
C36: Warden deployment comparison — 24GB worker at baseline active seconds
C37: MAU | D37: Active GPU h/month | E37: Warm Pod £/month | F37: Serverless active-only £/month | G37: Warm idle h/month | H37: Cold-start caveat
C38: 100 | D38: 0.66666667 | E38: 145.42906 | F38: 0.33940825 | G38: 729.33333 | H38: Serverless removes warm idle cost but can introduce start/queue latency; validate against live turn SLO before relying on it.
C39: 1000 | D39: 6.6666667 | E39: 145.42906 | F39: 3.3940825 | G39: 723.33333 | H39: Serverless removes warm idle cost but can introduce start/queue latency; validate against live turn SLO before relying on it.
C40: 10000 | D40: 66.666667 | E40: 145.42906 | F40: 33.940825 | G40: 663.33333 | H40: Serverless removes warm idle cost but can introduce start/queue latency; validate against live turn SLO before relying on it.

Sheet Image Ladder
C3: Image Cost Ladder — FLUX Options for SynapticGM
C5: Per 1 MP baseline, with filterability assessed as implementation controls rather than a guarantee of child suitability.
C6: (USD list price, £ planning translation, and cost per retained memorable image)
C8: Route | D8: 1 MP list price $ | E8: 1 MP £ | F8: Kid/adult filterability | G8: Cost per retained memorable £ | H8: Live implication | I8: Source / access date
C9: FLUX via OpenRouter — FLUX.2 Pro | D9: 0.03 | E9: =D9*Assumptions!$D$22 | F9: Provider-policy and SynapticGM gate required; model page exposes price, but no complete child-policy control was evidenced. | G9: =E9/(Assumptions!$D$61*Assumptions!$D$62) | H9: No list-price advantage over direct BFL at 1 MP. Use only if unified routing/logging is worth the account-level loading. | I9: OpenRouter FLUX.2 Pro, accessed 18 Aug 2026: https://openrouter.ai/black-forest-labs/flux.2-pro
C10: BFL direct — FLUX.2 Pro | D10: 0.03 | E10: =D10*Assumptions!$D$22 | F10: BFL exposes `safety_tolerance` and moderation statuses; usage policy bars harmful/minor sexual content. SynapticGM remains policy owner. | G10: =E10/(Assumptions!$D$61*Assumptions!$D$62) | H10: Cleanest direct relationship; async API; retrieve/re-host signed result rather than expose provider URL. | I10: BFL Pricing / Usage Policy, accessed 18 Aug 2026: https://docs.bfl.ai/quick_start/pricing ; https://bfl.ai/legal/usage-policy
C11: Replicate — FLUX.2 Pro | D11: 0.03 | E11: =D11*Assumptions!$D$22 | F11: Safety checker exists for Flux base / derivative fine-tunes and can be disabled for API custom safety. Configurable, but external kid policy required. | G11: =E11/(Assumptions!$D$61*Assumptions!$D$62) | H11: 1 MP no-reference baseline combines $0.015/run + $0.015 output MP; reference images add $0.015/MP. | I11: Replicate FLUX / Safety Checking, accessed 18 Aug 2026: https://replicate.com/black-forest-labs/flux-2-pro ; https://replicate.com/docs/topics/predictions/safety-checking
C12: fal — FLUX.2 Pro | D12: 0.03 | E12: =D12*Assumptions!$D$22 | F12: `enable_safety_checker` defaults true; blocked outputs are black and `has_nsfw_concepts` is reported. This is NSFW control, not complete child context policy. | G12: =E12/(Assumptions!$D$61*Assumptions!$D$62) | H12: Default-on provider safety knob is valuable defense-in-depth; add SynapticGM prompt+image policy before display. | I12: fal FLUX.2 Pro/API, accessed 18 Aug 2026: https://fal.ai/models/fal-ai/flux-2-pro ; https://fal.ai/models/fal-ai/flux-2/api
C13: Local ComfyUI — FLUX/open model | D13: GPU dependent | E13: GPU dependent | F13: Maximum control only if SynapticGM selects, tests, versions and operates local filters; no platform-wide universal filter. | G13: GPU/operator dependent | H13: Not zero. Active GPU £ + operator + safety/eval burden; calculate locally from workflow seconds and GPU quote. | I13: ComfyUI repository / Desktop docs, accessed 18 Aug 2026: https://github.com/Comfy-Org/ComfyUI ; https://docs.comfy.org/installation/desktop/overview
C15: Soft-skip policy
C16: Default trigger | D16: Do not generate merely because a turn exists. Generate only when a ledger-supported, player-visible, distinct moment passes the stated weekly cap and the prompt/image policy gate.
C17: Default cap | D17: One eligible image attempt per weekly active user per week, 60% WAU/MAU planning assumption. The workbook exposes 0%, 30%, and 70% soft-skip stress cases.
C18: Default skip | D18: 70% of cap-eligible image opportunities are soft-skipped to preserve the feeling of a memorable moment rather than turn-by-turn wallpaper.
C19: Paid output rule | D19: Assume a submitted image request can incur its listed fee. Do not assume provider-moderated, failed, duplicate, or rejected outputs are free unless billing documentation proves it.
C20: Display rule | D20: Run SynapticGM prompt and result policy before display. Treat provider NSFW/moderation as an additional layer, not the complete kid/adult decision.
C21: Metric | D21: Cash per retained memorable image = paid cost / (provider delivery success × memorable keep rate). Baseline uses 90% delivery success and 65% keep rate; change both in Assumptions.

Sheet Sources
C3: Fresh Price Sources and Model Caveats
C5: All vendor price pages accessed 18 Aug 2026. List prices may change; marketplace prices are snapshots, not commitments.
C6: (source log)
C8: Category | D8: Vendor / source | E8: Observed item used | F8: URL | G8: Access date | H8: Caveat
C9: Text narrator | D9: Anthropic | E9: Claude Sonnet 5: $2 input / $0.20 cache read / $2.50 5m write / $10 output per MTok | F9: https://docs.anthropic.com/en/docs/about-claude/pricing | G9: 2026-08-18 | H9: Direct API list price; cache writes and reads are distinct charges.
C10: Routing | D10: OpenRouter | E10: Pay-as-you-go platform fee shown as 5.5%; sticky prompt caching documentation | F10: https://openrouter.ai/pricing ; https://openrouter.ai/docs/guides/best-practices/prompt-caching | G10: 2026-08-18 | H10: Planning gross-up; model/provider rate and billing treatment must be verified in account.
C11: Hosted gate | D11: Fireworks | E11: Nemotron 3.5 Lightning 30B A3B: $0.05 / $0.01 cached / $0.20 output per MTok | F11: https://docs.fireworks.ai/serverless/pricing | G11: 2026-08-18 | H11: Model-specific serverless list price; no warm idle charge assumed.
C12: Direct low-cost reference | D12: DeepSeek | E12: V4 Flash off-peak: $0.007 cache hit / $0.22 miss / $0.66 output per MTok | F12: https://api-docs.deepseek.com/quick_start/pricing/ | G12: 2026-08-18 | H12: Peak/off-peak varies; not used as the base mid-narrator.
C13: 24GB GPU | D13: RunPod | E13: A5000 Pod $0.27/h; 24GB serverless group $0.69/h; 4090 Pod $0.74/h | F13: https://www.runpod.io/pricing | G13: 2026-08-18 | H13: Public on-demand quote; warm pod assumes 730 paid h/month.
C14: 80GB GPU | D14: RunPod | E14: A100 PCIe 80GB Pod $1.39/h; A100 SXM 80GB $1.59/h | F14: https://www.runpod.io/pricing | G14: 2026-08-18 | H14: Used for 70B capacity illustration; hardware fit/performance requires benchmark validation.
C15: GPU comparison | D15: Lambda | E15: A100 40GB $1.99/h; A100 80GB $2.79/h; no current public 24/48GB row observed | F15: https://lambda.ai/pricing | G15: 2026-08-18 | H15: Do not fabricate a current 24GB Lambda quote.
C16: GPU comparison | D16: Vast.ai | E16: Marketplace snapshot captured: RTX 3090 24GB $0.07/h; RTX 4090 24GB $0.13/h | F16: https://vast.ai/pricing ; https://vast.ai/pricing/gpu/RTX-4090 | G16: 2026-08-18 | H16: Marketplace offer, host/reliability/storage/bandwidth variable; do not use as production commitment baseline.
C17: Image | D17: BFL | E17: FLUX.2 Pro T2I from $0.03 first MP; 1 credit = $0.01 | F17: https://docs.bfl.ai/quick_start/pricing | G17: 2026-08-18 | H17: Resolution and input-editing dependent.
C18: Image | D18: OpenRouter | E18: FLUX.2 Pro $0.03 first output MP; $0.015 input MP for reference images | F18: https://openrouter.ai/black-forest-labs/flux.2-pro | G18: 2026-08-18 | H18: No assumed price advantage over direct BFL at 1MP.
C19: Image | D19: Replicate | E19: FLUX.2 Pro $0.015/run plus $0.015 per output/input MP in source sweep | F19: https://replicate.com/black-forest-labs/flux-2-pro | G19: 2026-08-18 | H19: Safety needs separate policy; model-page pricing basis is version-specific.
... C22: FX | D22: Bank of England | E22: 17 Aug 2026: £1 = $1.3553; model uses $1 = £0.73784 | F22: https://www.bankofengland.co.uk/boeapps/database/Rates.asp | G22: 2026-08-18 | H22: BoE calls these non-official rates; planning translation only.
